<?xml version="1.0" encoding="UTF-8"?>
<testsuite errors="0" failures="1" file="PrivilegeDecorator_tests.py" name="PrivilegeDecorator_tests.PrivilegeDecorator_test-20191030171220" skipped="0" tests="1" time="0.001" timestamp="2019-10-30T17:12:20">
	<testcase classname="PrivilegeDecorator_tests.PrivilegeDecorator_test" file="src/unittest/python/PrivilegeDecorator_tests.py" line="13" name="test_user" time="0.001" timestamp="2019-10-30T17:12:20">
		<failure message="&lt;DummyUser id=139921582914024&gt; != None" type="AssertionError">
<![CDATA[Traceback (most recent call last):
  File "/home/joseluis/Documentos/ITESO/DSO/decorator-practice/python/src/unittest/python/PrivilegeDecorator_tests.py", line 14, in test_user
    self.assertEqual(self.mockedUser,self.priv.user())
AssertionError: <DummyUser id=139921582914024> != None
]]>		</failure>
		<system-out>
<![CDATA[]]>		</system-out>
		<system-err>
<![CDATA[]]>		</system-err>
	</testcase>
</testsuite>
